Workbook

Sheet Data
A1: n | B1: name | C1: dept | D1: salary | E1: hired
A2: 1 | B2: Ada | C2: Eng | D2: 165000 | E2: 2019-03-01
A3: 2 | B3: Grace | C3: Eng | D3: 172000 | E3: 2018-07-15
A4: 3 | B4: Katherine | C4: Science | D4: 158000 | E4: 2020-01-20
A5: 4 | B5: Dorothy | C5: Science | D5: 149000 | E5: 2021-11-02
A6: 5 | B6: Margaret | C6: Eng | D6: 181000 | E6: 2017-05-30
A7: 6 | B7: Annie | C7: Ops | D7: 121000 | E7: 2022-09-12
A8: 7 | B8: Henrietta | C8: Ops | D8: 118000 | E8: 2023-02-28
A9: 8 | B9: Mary | C9: Science | D9: 143000 | E9: 2020-06-08

Sheet Formulas
A1: case | B1: formula | C1: result
A2: SUM | B2: '=SUM(Data!D2:D9) | C2: =SUM(Data!D2:D9) -> 1207000
A3: AVERAGE | B3: '=AVERAGE(Data!D2:D9) | C3: =AVERAGE(Data!D2:D9) -> 150875
A4: MIN | B4: '=MIN(Data!D2:D9) | C4: =MIN(Data!D2:D9) -> 118000
A5: MAX | B5: '=MAX(Data!D2:D9) | C5: =MAX(Data!D2:D9) -> 181000
A6: COUNT | B6: '=COUNT(Data!D2:D9) | C6: =COUNT(Data!D2:D9) -> 8
A7: COUNTA | B7: '=COUNTA(Data!A1:E9) | C7: =COUNTA(Data!A1:E9) -> 45
A8: COUNTBLANK | B8: '=COUNTBLANK(Data!A1:E20) | C8: =COUNTBLANK(Data!A1:E20) -> 55
A9: MEDIAN | B9: '=MEDIAN(Data!D2:D9) | C9: =MEDIAN(Data!D2:D9) -> 153500
A10: STDEV.S | B10: '=STDEV.S(Data!D2:D9) | C10: =_xlfn.STDEV.S(Data!D2:D9) -> 22812.512
A11: VAR.S | B11: '=VAR.S(Data!D2:D9) | C11: =_xlfn.VAR.S(Data!D2:D9) -> 5.2041071e+08
A12: SUMIF | B12: '=SUMIF(Data!C2:C9,"Eng",Data!D2:D9) | C12: =SUMIF(Data!C2:C9,"Eng",Data!D2:D9) -> 518000
A13: SUMIFS | B13: '=SUMIFS(Data!D2:D9,Data!C2:C9,"Eng",Data!D2:D9,">170000") | C13: =SUMIFS(Data!D2:D9,Data!C2:C9,"Eng",Data!D2:D9,">170000") -> 353000
A14: COUNTIF | B14: '=COUNTIF(Data!C2:C9,"Science") | C14: =COUNTIF(Data!C2:C9,"Science") -> 3
A15: COUNTIFS | B15: '=COUNTIFS(Data!C2:C9,"Ops",Data!D2:D9,"<120000") | C15: =COUNTIFS(Data!C2:C9,"Ops",Data!D2:D9,"<120000") -> 1
A16: AVERAGEIF | B16: '=AVERAGEIF(Data!C2:C9,"Eng",Data!D2:D9) | C16: =AVERAGEIF(Data!C2:C9,"Eng",Data!D2:D9) -> 172666.67
A17: IF | B17: '=IF(Data!D2>160000,"high","low") | C17: =IF(Data!D2>160000,"high","low") -> high
A18: IFS | B18: '=IFS(Data!D2>180000,"top",Data!D2>150000,"mid",TRUE,"base") | C18: =_xlfn.IFS(Data!D2>180000,"top",Data!D2>150000,"mid",TRUE(),"base") -> mid
A19: AND | B19: '=AND(1=1,2=2) | C19: =AND(1=1,2=2) -> TRUE
A20: OR | B20: '=OR(1=2,2=2) | C20: =OR(1=2,2=2) -> TRUE
A21: NOT | B21: '=NOT(1=2) | C21: =NOT(1=2) -> TRUE
A22: XOR | B22: '=XOR(TRUE,FALSE) | C22: =_xlfn.XOR(TRUE(),FALSE()) -> TRUE
A23: IFERROR | B23: '=IFERROR(1/0,"caught") | C23: =IFERROR(1/0,"caught") -> caught
A24: IFNA | B24: '=IFNA(NA(),"was na") | C24: =_xlfn.IFNA(NA(),"was na") -> was na
A25: VLOOKUP | B25: '=VLOOKUP(3,Data!A2:D9,2,FALSE) | C25: =VLOOKUP(3,Data!A2:D9,2,FALSE()) -> Katherine
A26: HLOOKUP | B26: '=HLOOKUP("dept",Data!A1:E9,4,FALSE) | C26: =HLOOKUP("dept",Data!A1:E9,4,FALSE()) -> Science
A27: INDEX_MATCH | B27: '=INDEX(Data!D2:D9,MATCH("Grace",Data!B2:B9,0)) | C27: =INDEX(Data!D2:D9,MATCH("Grace",Data!B2:B9,0)) -> 172000
A28: XLOOKUP | B28: '=XLOOKUP("Annie",Data!B2:B9,Data!D2:D9,"none") | C28: =_xlfn.xlookup("Annie",Data!B2:B9,Data!D2:D9,"none") -> #NAME?
A29: XMATCH | B29: '=XMATCH("Mary",Data!B2:B9,0) | C29: =_xlfn.xmatch("Mary",Data!B2:B9,0) -> #NAME?
A30: OFFSET | B30: '=OFFSET(Data!A1,2,3) | C30: =OFFSET(Data!A1,2,3) -> 172000
A31: INDIRECT | B31: '=INDIRECT("Data!D2") | C31: =INDIRECT("Data!D2") -> 165000
A32: CHOOSE | B32: '=CHOOSE(2,"a","b","c") | C32: =CHOOSE(2,"a","b","c") -> b
A33: ROW | B33: '=ROW(Data!A5) | C33: =ROW(Data!A5) -> 5
A34: COLUMN | B34: '=COLUMN(Data!D1) | C34: =COLUMN(Data!D1) -> 4
A35: ROWS | B35: '=ROWS(Data!A1:A9) | C35: =ROWS(Data!A1:A9) -> 9
A36: COLUMNS | B36: '=COLUMNS(Data!A1:E1) | C36: =COLUMNS(Data!A1:E1) -> 5
A37: CONCAT | B37: '=CONCAT("a","b","c") | C37: =_xlfn.CONCAT("a","b","c") -> abc
A38: TEXTJOIN | B38: '=TEXTJOIN("-",TRUE,"x","y","z") | C38: =_xlfn.TEXTJOIN("-",TRUE(),"x","y","z") -> x-y-z
A39: LEFT | B39: '=LEFT("spreadsheet",6) | C39: =LEFT("spreadsheet",6) -> spread
A40: RIGHT | B40: '=RIGHT("spreadsheet",5) | C40: =RIGHT("spreadsheet",5) -> sheet
...
