Workbook

Sheet D
A1: 4 | B1: 2 | C1: a | D1: 1 | E1: 10 | G1: 2.1 | H1: 1 | I1: 3 | J1: 6
A2: 5 | B2: 4 | C2: b | D2: 2 | E2: x | G2: 4.3 | H2: 2 | I2: 1 | J2: 9
A3: 8 | B3: 6 | C3: a | D3: 3 | E3: TRUE | G3: 5.9 | H3: 3 | I3: 4 | J3: 4
A4: 7 | B4: 8 | C4: c | D4: 4 | G4: 8.4 | H4: 4 | I4: 1 | J4: 8
A5: 11 | B5: 10 | D5: 5 | E5: 20 | G5: 10.1 | H5: 5 | I5: 5 | J5: 7
A6: 4 | B6: 12 | D6: 6 | J6: 5
A7: 3 | B7: 14 | D7: 7
A8: 9 | B8: 16 | D8: 8

Sheet C
A1: case1 | B1: =AVERAGE(D!A1:A8)
A2: case2 | B2: =AVERAGEA(D!E1:E5)
A3: case3 | B3: =AVERAGE(D!E1:E5)
A4: case4 | B4: =COUNT(D!E1:E5)
A5: case5 | B5: =COUNTA(D!E1:E5)
A6: case6 | B6: =COUNTBLANK(D!E1:E8)
A7: case7 | B7: =COUNT(1,)
A8: case8 | B8: =COUNTA(1,)
A9: case9 | B9: =COUNTA("")
A10: case10 | B10: =COUNT("3")
A11: case11 | B11: =COUNT(TRUE)
A12: case12 | B12: =COUNTA(D!F1:F5)
A13: case13 | B13: =MAX(D!A1:A8)
A14: case14 | B14: =MIN(D!A1:A8)
A15: case15 | B15: =MAXA(D!E1:E5)
A16: case16 | B16: =MINA(D!E1:E5)
A17: case17 | B17: =MEDIAN(D!A1:A8)
A18: case18 | B18: =MEDIAN(D!A1:A7)
A19: case19 | B19: =_xlfn.MODE.SNGL(D!A1:A8)
A20: case20 | B20: =_xlfn.MODE.SNGL(D!D1:D8)
A21: case21 | B21: =LARGE(D!A1:A8,3)
A22: case22 | B22: =SMALL(D!A1:A8,3)
A23: case23 | B23: =_xlfn.RANK.EQ(4,D!A1:A8)
A24: case24 | B24: =_xlfn.RANK.EQ(4,D!A1:A8,1)
A25: case25 | B25: =_xlfn.RANK.AVG(4,D!A1:A8)
A26: case26 | B26: =_xlfn.PERCENTILE.INC(D!A1:A8,0.25)
A27: case27 | B27: =_xlfn.PERCENTILE.EXC(D!A1:A8,0.25)
A28: case28 | B28: =_xlfn.QUARTILE.INC(D!A1:A8,1)
A29: case29 | B29: =_xlfn.QUARTILE.EXC(D!A1:A8,1)
A30: case30 | B30: =_xlfn.PERCENTRANK.INC(D!A1:A8,7)
A31: case31 | B31: =_xlfn.PERCENTRANK.EXC(D!A1:A8,7)
A32: case32 | B32: =_xlfn.PERCENTRANK.INC(D!A1:A8,6)
A33: case33 | B33: =_xlfn.PERCENTRANK.INC(D!A1:A8,3,5)
A34: case34 | B34: =_xlfn.STDEV.S(D!A1:A8)
A35: case35 | B35: =_xlfn.STDEV.P(D!A1:A8)
A36: case36 | B36: =STDEVA(D!E1:E5)
A37: case37 | B37: =STDEVPA(D!E1:E5)
A38: case38 | B38: =_xlfn.VAR.S(D!A1:A8)
A39: case39 | B39: =_xlfn.VAR.P(D!A1:A8)
A40: case40 | B40: =VARA(D!E1:E5)
...
